
# ## **Why Use Exception Handling?**

# *   **Prevents Program Crashes**: Ensures your program doesnâ€™t terminate abruptly due to unexpected errors.

# *   **Graceful Error Recovery**: Allows you to handle errors gracefully and provide meaningful feedback to users.
# *   **Clean Code**: Separates error-handling logic from the main program flow, making code more readable and maintainable.
# *   **Resource Management**: Ensures resources (e.g., files, connections) are properly released, even if an error occurs.



# try:
#     print(10/0)
# except ZeroDivisionError:
#     print(ZeroDivisionError)



# import random
# from typing import Tuple, Dict, List

# def generate_random_data(num_samples: int) -> List[Tuple[int, int]]:
#     """Generates a list of random number pairs."""
#     try:
#         if not isinstance(num_samples, int) or num_samples <= 0:
#             raise ValueError("Number of samples must be a positive integer.")
#         data = [(random.randint(1, 100), random.randint(1, 100)) for _ in range(num_samples)]
#         return data
#     except ValueError as ve:
#         print(f"Error: {ve}")
#         return []  # Return empty list on error
#     except Exception as e: # Catch any other unexpected errors
#         print(f"An unexpected error occurred: {e}")
#         return []

# # print(generate_random_data(00000))



# def terminate_program():
#     """Terminates the program by raising an exception."""
#     raise SystemExit("Program is terminating.")

# terminate_program()




# try:
#     try:
#         raise ValueError("Inner")
#     except ValueError as e:
#         print("Caught inner:", e)
#         raise
# except ValueError as e:
#     print("Caught outer:", e)



#  becasue inner try raise the error and then reraised the error throgh raise keyword



# def test():
#     try:
#         return 3 
#     except:
#         return 6
#     else:
#         return 10
    
# print(test())

#  why is happening now because of try already return the valuse it function did not reach at else bloack


# try:
#     x = int("abc")
#     y = 5 / 0
# except ValueError:
#     print("Conversion failed")
# except ZeroDivisionError:
#     print("Divide by zero")

# because eror check that is in int("int")



# try:
#     raise KeyboardInterrupt("DASDASDasdasd")
# except BaseException:
#     print("Handled")
# finally:
#     print("Cleanup")




# try:
#     print("A")
#     raise KeyboardInterrupt("Stop")
# except Exception:  # because is not builtin eception error occured
#     print("B")
# finally:
#     print("C")



# ERROR HANDLING WITH FILE 
# import os

# current_dir = f"{os.getcwd()}/py-teach"

# try:
#     file = open(f"{current_dir}/mhamil.txt", "r")
#     data= file.read()
#     print(data)
# except FileNotFoundError as e:
#     print(f"your file mhamil.txt is{e}")
# except PermissionError:
#     print("Error :  Permission denied")
# else:
#     print("file has got successfully")
# finally:
#     try:
#         file.close()
#     except NameError:
#         print("ther are not file to access")
   
     



# def final_boss():
#     try:
#         raise ValueError("Outer Error")
#     except ValueError as e:
#         try:
#             raise KeyError("Inner Error")
#         except KeyError as ke:
#             raise RuntimeError("Final Blow") from e
#         finally:
#             print("Inner finally running")
#     finally:
#         print("Outer finally running")

# final_boss()



def final_boss():
    try:
        x = 1/ 0
        raise ZeroDivisionError("Outer Error")
    except ValueError as e:
        try:
            raise KeyError("Inner Error")
        except KeyError as ke:
            raise RuntimeError("Final Blow") from e   # isthis case frrom e means cause  error is "e" ValuseError()
        finally:
            print("Inner finally running")
    finally:
        print("Outer finally running")

# try:
#     final_boss()
# except Exception as ex:
#     print("Caught:", ex)
#     print("Cause:", ex.__cause__)



# def callERror():
#     try:
#         final_boss()
#     finally:
#         print("error ayega")

# callERror()

        




